Workbook

Sheet Halfling
A1: Giocatore | B1: Azzeil Summerhill | G1: Agile Furtivo Preciso | K1: Esperienza | N1: 30.000
A2: Razza | B2: Halfling | E2: Classe | G2: Halfling | I2: 5° | K2: Allineamento | N2: Neutrale
A4: CA | B4: 3 | E4: Slot | F4: 20 | G4: +7 | H4: ½ Mov. | L4: Iniziativa | M4: 2 | O4: PF | P4: 25
A5: Abilità | J5: Mod. | M5: Tiri salvezza
A6: 14 | B6: FOR | C6: Apre porte bloccate con 1-3 su 1d6 | J6: 1 | M6: Veleno, Raggio della Morte | P6: 6
A7: 14 | B7: DES | C7: Bonus a attacchi a distanza, CA, iniziativa | J7: 1 | M7: Bacchetta | P7: 7
A8: 9 | B8: COS | C8: Nessun modificatore | J8: 0 | M8: Pietrificazione Paralisi | P8: 8
A9: 13 | B9: INT | C9: Legge e scrive più lingue | J9: 1 | M9: Soffio Drago | P9: 10
A10: 12 | B10: SAG | C10: Nessun modificatore | J10: 0 | M10: Incantesimi Bastone Magico | P10: 10
A11: 11 | B11: CAR | C11: Reazioni PNG +0, massimo 4 seguaci, morale seguaci 7 | J11: 0 | M11: TS: 1D20 ≥ valore TS = Successo TA: 1D20 ≤ valore attributo = Successo
A13: Lingue Parlate | D13: Movimento | H13: Piedi | I13: Metri | J13: Quad. | K13: Sprint | L13: Malus | N13: Slot/Equipaggiamento
A14: Common, Nanco, Gnomesco, Koboldo,Goblin | D14: Combattimento | G14: 1R | H14: 20 | I14: =J14*1.5 -> 6 | J14: =H14/5 -> 4 | K14: 8 dm | L14: - | N14: 2/Cotta di maglia
D15: Esplorazione | G15: 1T | H15: =H14*3 -> 60 | I15: =J15*1.5 -> 18 | J15: =H15/5 -> 12 | K15: - | L15: - | N15: 1/Pugnali (2)
D16: Correre | G16: 1R | H16: =H14*3 -> 60 | I16: =J16*1.5 -> 18 | J16: =H16/5 -> 12 | K16: =J16+(J16/2) -> 18 | L16: -2 Tiri 10R (max 3 R) | N16: 1/Sacchetto Pietre
A17: THAC0 - Tiro = CA Colpita | D17: Arrampicarsi | G17: 1R | H17: =H14/2 -> 10 | I17: =J17*1.5 -> 3 | J17: =H17/5 -> 2 | K17: =J17+(J17/2) -> 3 | N17: 0/Vestiti, Cintura, Stivali
A18: 1R = 10 Sec. | 1T = 10 Min. | D18: Nuotare | G18: 1R | H18: =H14/2 -> 10 | I18: =J18*1.5 -> 3 | J18: =H18/5 -> 2 | K18: =J18+(J18/2) -> 3 | N18: 1/Fionda
D19: Giornaliero | G19: 1G | H19: 12mi | I19: 19km | K19: - | L19: - | N19: 1/Spada Corta + 1
N20: 2/Scudo
A21: Carica +2TxC +2CA min.4□ | Ritirata difensiva ½Mv nega attacco nemico | Difesa totale -2CA ½Mv
A22: Spinta 1d20+mod.FOR vs +1□ | Disarmo -4TxC | Parare(F) -4CA ½Mv | Colpo potente(F) -5TxC +5PF | O22: Slot | P22: 8
A23: Afferrrare TxC vs CA, Liberarsi da presa 1d20+mod.FOR vs, Azione Pronta inter. turno nemico
A24: Scambiare Posizione ½Mv | Attraversare alleati +1□ | Passare oggetto: chi passa usa azione | O24: Banca | P24: Trasportati
A25: Combattimento in fila: 2* fila armi lunghe | Preparare per carica Dannox2 | N25: pp
A26: Prone: +2 TxC nemici, ½Mv per alzarsi | Raccolgiere arma: Mov.+Racc. o Racc.+Att. | N26: mo | P26: 500
A27: Copertura: Parziale -2TxC +2CA, Quasi Tot. -4TxC +4CA | Area: Parz. +2 TS, Quasi Tot. +4 TS | N27: ma
A28: Tiro oltre 1* PG/Mostri: -2TxC Lancio/-4TxC Tiro, 1/1-2 Colpito Alleato | N28: mr
A29: TxC Distanza: corta +1, normale 0, lunga -1 | O29: Slot | P29: 5
N32: Abilità
A33: Halfling vs Nemici Grandi: +2 CA contro creature più grandi di un umano | N33: 1/6 trovare porte segrete
A34: All'aperto (boschi/sottobosco): 90% di non essere individuato | N34: 2/6 Ascoltare rumori
A35: In dungeon (ombre, fermo e silenzioso): 1-2 su 1d6 di non essere visto | N35: 1/6 ascoltare attr. Porte
L40: THAC0
A41: Arma | B41: Range | C41: AC 9 | D41: 8 | E41: =D41-1 -> 7 | F41: =E41-1 -> 6 | G41: =F41-1 -> 5 | H41: =G41-1 -> 4 | I41: =H41-1 -> 3 | J41: =I41-1 -> 2 | K41: =J41-1 -> 1 | L41: =K41-1 -> 0 | M41: Danno | O41: Note
A42: Spada Corta | B42: melee | C42: 6 | D42: =C42+1 -> 7 | E42: =D42+1 -> 8 | F42: =E42+1 -> 9 | G42: =F42+1 -> 10 | H42: =G42+1 -> 11 | I42: =H42+1 -> 12 | J42: =I42+1 -> 13 | K42: =J42+1 -> 14 | L42: =K42+1 -> 15 | M42: 1d6+2
A43: Pugnale | B43: melee | C43: 7 | D43: =C43+1 -> 8 | E43: =D43+1 -> 9 | F43: =E43+1 -> 10 | G43: =F43+1 -> 11 | H43: =G43+1 -> 12 | I43: =H43+1 -> 13 | J43: =I43+1 -> 14 | K43: =J43+1 -> 15 | L43: =K43+1 -> 16 | M43: 1d4+1 | O43: lanciabile 10/20/30'
A44: Fionda | B44: 40/80/160' | C44: 8 | D44: =C44+1 -> 9 | E44: =D44+1 -> 10 | F44: =E44+1 -> 11 | G44: =F44+1 -> 12 | H44: =G44+1 -> 13 | I44: =H44+1 -> 14 | J44: =I44+1 -> 15 | K44: =J44+1 -> 16 | L44: =K44+1 -> 17 | M44: 1d4 | O44: 20 Pietre

Sheet Retro A
A1: Slot Totali | C1: =Halfling!F4 -> 20 | E1: Sovraccarico | G1: =Halfling!G4 -> +7 | I1: Slot Bonus | M1: Slot Occupati | O1: =Halfling!P22+Halfling!P29 -> 13
A2: Oggetto | H2: Qt. | I2: Slot | J2: STATS
A3: 1 | J3: PF
A4: =A3+1 -> 2
A5: =A4+1 -> 3
A6: =A5+1 -> 4 | J6: THACO0
A7: =A6+1 -> 5 | J7: +TS | K7: V | L7: B | M7: P | N7: S | O7: I
A8: =A7+1 -> 6 | J8: CA
A9: =A8+1 -> 7 | J9: 1 liv.
A10: =A9+1 -> 8 | J10: 2 liv.
A11: =A10+1 -> 9 | J11: 3 liv.
A12: =A11+1 -> 10 | J12: 4 liv.
A13: =A12+1 -> 11 | J13: 5 liv.
A14: =A13+1 -> 12 | J14: Cariche
A15: =A14+1 -> 13 | J15: A. Santa
A16: =A15+1 -> 14 | J16: Olio
A17: =A16+1 -> 15 | J17: Torcie
A18: =A17+1 -> 16 | J18: Dardi
A19: =A18+1 -> 17 | J19: Quadrelli
... A22: =A21+1 -> 20 | J22: Pietre
Q23: =10
A24: THAC0 | C24: CA | D24: CA | E24: CA | F24: CA | G24: CA | H24: CA | I24: CA | J24: CA | K24: CA | L24: CA | M24: CA | N24: CA | O24: CA | P24: CA | Q24: CA
C25: -3 | D25: =C25+1 -> -2 | E25: =D25+1 -> -1 | F25: =E25+1 -> 0 | G25: =F25+1 -> 1 | H25: =G25+1 -> 2 | I25: =H25+1 -> 3 | J25: =I25+1 -> 4 | K25: =J25+1 -> 5 | ... Q25: =P25+1 -> 11
A26: 19 | C26: =$A26-C$25 -> 22 | D26: =$A26-D$25 -> 21 | E26: =$A26-E$25 -> 20 | F26: =$A26-F$25 -> 19 | G26: =$A26-G$25 -> 18 | H26: =$A26-H$25 -> 17 | I26: =$A26-I$25 -> 16 | J26: =$A26-J$25 -> 15 | ... Q26: =$A26-Q$25 -> 8
A27: 18 | C27: =$A27-C$25 -> 21 | D27: =$A27-D$25 -> 20 | E27: =$A27-E$25 -> 19 | F27: =$A27-F$25 -> 18 | G27: =$A27-G$25 -> 17 | H27: =$A27-H$25 -> 16 | I27: =$A27-I$25 -> 15 | J27: =$A27-J$25 -> 14 | ... Q27: =$A27-Q$25 -> 7
A28: 17 | C28: =$A28-C$25 -> 20 | D28: =$A28-D$25 -> 19 | E28: =$A28-E$25 -> 18 | F28: =$A28-F$25 -> 17 | G28: =$A28-G$25 -> 16 | H28: =$A28-H$25 -> 15 | I28: =$A28-I$25 -> 14 | J28: =$A28-J$25 -> 13 | ... Q28: =$A28-Q$25 -> 6
A29: 16 | C29: =$A29-C$25 -> 19 | D29: =$A29-D$25 -> 18 | E29: =$A29-E$25 -> 17 | F29: =$A29-F$25 -> 16 | G29: =$A29-G$25 -> 15 | H29: =$A29-H$25 -> 14 | I29: =$A29-I$25 -> 13 | J29: =$A29-J$25 -> 12 | ... Q29: =$A29-Q$25 -> 5
A30: 15 | C30: =$A30-C$25 -> 18 | D30: =$A30-D$25 -> 17 | E30: =$A30-E$25 -> 16 | F30: =$A30-F$25 -> 15 | G30: =$A30-G$25 -> 14 | H30: =$A30-H$25 -> 13 | I30: =$A30-I$25 -> 12 | J30: =$A30-J$25 -> 11 | ... Q30: =$A30-Q$25 -> 4
A31: 14 | C31: =$A31-C$25 -> 17 | D31: =$A31-D$25 -> 16 | E31: =$A31-E$25 -> 15 | F31: =$A31-F$25 -> 14 | G31: =$A31-G$25 -> 13 | H31: =$A31-H$25 -> 12 | I31: =$A31-I$25 -> 11 | J31: =$A31-J$25 -> 10 | ... Q31: =$A31-Q$25 -> 3
A32: 13 | C32: =$A32-C$25 -> 16 | D32: =$A32-D$25 -> 15 | E32: =$A32-E$25 -> 14 | F32: =$A32-F$25 -> 13 | G32: =$A32-G$25 -> 12 | H32: =$A32-H$25 -> 11 | I32: =$A32-I$25 -> 10 | J32: =$A32-J$25 -> 9 | ... Q32: =$A32-Q$25 -> 2
A33: 12 | C33: =$A33-C$25 -> 15 | D33: =$A33-D$25 -> 14 | E33: =$A33-E$25 -> 13 | F33: =$A33-F$25 -> 12 | G33: =$A33-G$25 -> 11 | H33: =$A33-H$25 -> 10 | I33: =$A33-I$25 -> 9 | J33: =$A33-J$25 -> 8 | ... Q33: =$A33-Q$25 -> 1
A34: 11 | C34: =$A34-C$25 -> 14 | D34: =$A34-D$25 -> 13 | E34: =$A34-E$25 -> 12 | F34: =$A34-F$25 -> 11 | G34: =$A34-G$25 -> 10 | H34: =$A34-H$25 -> 9 | I34: =$A34-I$25 -> 8 | J34: =$A34-J$25 -> 7 | ... Q34: =$A34-Q$25 -> 0
Q35: THAC0 - Tiro = CA Colpita
A37: Slot | B37: Esempio | K37: Armatura | M37: CA | N37: Slot | O37: U/E | P37: N | Q37: H
A38: 0 | B38: Anelli, amuleti, pergamene, chiavi, gemme | K38: Nessuna | M38: 9 | N38: 0 | O38: 40' | P38: 20' | Q38: 30'
A39: 1/3 | B39: Pozioni, acqua santa (fiale) | K39: Imbottita | M39: 8 | N39: 1 | O39: 40' | P39: 20' | Q39: 30'
A40: 1/2 | B40: Olio (fiasche) | K40: Cuoio | M40: 7 | N40: 2 | P40: 20' | Q40: 30'
A41: 1 | B41: Armi piccole, torce (6), corda, faretra, bacchette, sacco (+3 slot) | K41: Cuoio Borchiato | M41: 6 | N41: 2 | O41: 40' | P41: 20' | Q41: 30'
A42: 2 | B42: Armi medie, arm. leggere, scudo, arco c., balestra l., stivali, mantello | K42: Cotta di maglie | M42: 5 | N42: 2 | O42: 30' | P42: 20' | Q42: 20'
A43: 3 | B43: Armi grandi, armatura pesante, scudo grande, arco lungo, balestra p. | K43: Arm. a bande | M43: 4 | N43: 3 | O43: 20' | P43: 20' | Q43: -
...

Sheet Elf
A1: Giocatore | B1: Conno Darhov | G1: Guerriero Arcano Versatile | K1: Esperienza | N1: 33,650
A2: Razza | B2: Elfo | E2: Classe | G2: Elfo | I2: 5° | K2: Allineamento | N2: Neutrale
A4: CA | B4: 4 | E4: Slot | F4: 24 | G4: +8 | H4: ½ Mov. | L4: Iniziativa | M4: 0 | O4: PF | P4: 30
A5: Abilità | J5: Mod. | M5: Tiri salvezza
A6: 16 | B6: FOR | C6: Apre porte bloccate con 1-4 su 1d6 | J6: 2 | M6: Veleno, Raggio della Morte | P6: 10
A7: 12 | B7: DES | C7: Nessun modificatore | J7: 0 | M7: Bacchetta | P7: 11
A8: 13 | B8: COS | C8: Bonus punti ferita aggiunti al totale | J8: 1 | M8: Pietrificazione Paralisi | P8: 11
A9: 17 | B9: INT | C9: Legge e scrive più lingue | J9: 2 | M9: Soffio Drago | P9: 13
A10: 11 | B10: SAG | C10: Nessun modificatore | J10: 0 | M10: Incantesimi Bastone Magico | P10: 12
A11: 10 | B11: CAR | C11: Reazioni PNG +0, massimo 4 seguaci, morale seguaci 7 | J11: 0 | M11: TS: 1D20 ≥ valore TS = Successo TA: 1D20 ≤ valore attributo = Successo
A13: Lingue Parlate | D13: Movimento | H13: Piedi | I13: Metri | J13: Quad. | K13: Sprint | L13: Malus | N13: Slot/Equipaggiamento
A14: Common, Nanco, Gnomesco, Koboldo,Goblin | D14: Combattimento | G14: 1R | H14: 30 | I14: =J14*1.5 -> 9 | J14: =H14/5 -> 6 | K14: 12 dm | L14: - | N14: 2/Cotta di maglia
D15: Esplorazione | G15: 1T | H15: =H14*3 -> 90 | I15: =J15*1.5 -> 27 | J15: =H15/5 -> 18 | K15: - | L15: - | N15: 1/Pugnali (2)
D16: Correre | G16: 1R | H16: =H14*3 -> 90 | I16: =J16*1.5 -> 27 | J16: =H16/5 -> 18 | K16: =J16+(J16/2) -> 27 | L16: -2 Tiri 10R (max 3 R) | N16: 2/Spada + 1
A17: THAC0 - Tiro = CA Colpita | D17: Arrampicarsi | G17: 1R | H17: =H14/2 -> 15 | I17: =J17*1.5 -> 4.5 | J17: =H17/5 -> 3 | K17: =J17+(J17/2) -> 4.5 | N17: 3/Arco Lungo
A18: 1R = 10 Sec. | 1T = 10 Min. | D18: Nuotare | G18: 1R | H18: =H14/2 -> 15 | I18: =J18*1.5 -> 4.5 | J18: =H18/5 -> 3 | K18: =J18+(J18/2) -> 4.5 | N18: 0/Vestiti, Cintura, Stivali
D19: Giornaliero | G19: 1G | H19: 18mi | I19: 29km | K19: - | L19: - | N19: 1/Libro Incantesimi
N20: 1/Faretra
A21: Carica +2TxC +2CA min.4□ | Ritirata difensiva ½Mv nega attacco nemico | Difesa totale -2CA ½Mv | N21: 2/Scudo
A22: Spinta 1d20+mod.FOR vs +1□ | Disarmo -4TxC | Parare(F) -4CA ½Mv | Colpo potente(F) -5TxC +5PF | O22: Slot | P22: 12
A23: Afferrrare TxC vs CA, Liberarsi da presa 1d20+mod.FOR vs, Azione Pronta inter. turno nemico
A24: Scambiare Posizione ½Mv | Attraversare alleati +1□ | Passare oggetto: chi passa usa azione | O24: Banca | P24: Trasportati
A25: Combattimento in fila: 2* fila armi lunghe | Preparare per carica Dannox2 | N25: pp
A26: Prone: +2 TxC nemici, ½Mv per alzarsi | Raccolgiere arma: Mov.+Racc. o Racc.+Att. | N26: mo | P26: 500
A27: Copertura: Parziale -2TxC +2CA, Quasi Tot. -4TxC +4CA | Area: Parz. +2 TS, Quasi Tot. +4 TS | N27: ma
A28: Tiro oltre 1* PG/Mostri: -2TxC Lancio/-4TxC Tiro, 1/1-2 Colpito Alleato | N28: mr
A29: TxC Distanza: corta +1, normale 0, lunga -1 | O29: Slot | P29: 5
A31: Incantesimi Scelti | C31: 1°/2 | E31: 2°/2 | G31: 3°/1 | N31: Abilità
A32: 1 Livello | B32: Dardo Incantato 2d6+2 150' x 2 | N32: 2/6 trovare porte segrete
A33: 2 Livello | B33: Immagine Speculare 1d4 6T, Scassinare 60' | N33: 1/6 Ascoltare rumori
A34: 3 Livello | B34: Fulmine 5d6 60'x5' | N34: 2/6 ascoltare attr. Porte
N35: Immune paralisi Ghoul
L40: THAC0
A41: Arma | B41: Range | C41: AC 9 | D41: 8 | E41: =D41-1 -> 7 | F41: =E41-1 -> 6 | G41: =F41-1 -> 5 | H41: =G41-1 -> 4 | I41: =H41-1 -> 3 | J41: =I41-1 -> 2 | K41: =J41-1 -> 1 | L41: =K41-1 -> 0 | M41: Danno | O41: Note
A42: Spada | B42: melee | C42: 5 | D42: =C42+1 -> 6 | E42: =D42+1 -> 7 | F42: =E42+1 -> 8 | G42: =F42+1 -> 9 | H42: =G42+1 -> 10 | I42: =H42+1 -> 11 | J42: =I42+1 -> 12 | K42: =J42+1 -> 13 | L42: =K42+1 -> 14 | M42: 1d8+3
A43: Pugnale | B43: melee | C43: 6 | D43: =C43+1 -> 7 | E43: =D43+1 -> 8 | F43: =E43+1 -> 9 | G43: =F43+1 -> 10 | H43: =G43+1 -> 11 | I43: =H43+1 -> 12 | J43: =I43+1 -> 13 | K43: =J43+1 -> 14 | L43: =K43+1 -> 15 | M43: 1d4+2 | O43: lanciabile 10/20/30'
A44: Arco Lungo | B44: 70/140/210' | C44: 8 | D44: =C44+1 -> 9 | E44: =D44+1 -> 10 | F44: =E44+1 -> 11 | G44: =F44+1 -> 12 | H44: =G44+1 -> 13 | I44: =H44+1 -> 14 | J44: =I44+1 -> 15 | K44: =J44+1 -> 16 | L44: =K44+1 -> 17 | M44: 1d6 | O44: 12 freccie

Sheet Retro E
A1: Slot Totali | C1: =Elf!F4 -> 24 | E1: Sovraccarico | G1: =Elf!G4 -> +8 | I1: Slot Bonus | M1: Slot Occupati | O1: =Elf!P22+Elf!P29 -> 17
A2: Oggetto | H2: Qt. | I2: Slot | J2: STATS
A3: 1 | J3: PF
A4: =A3+1 -> 2
A5: =A4+1 -> 3
A6: =A5+1 -> 4 | J6: THACO0
A7: =A6+1 -> 5 | J7: +TS | K7: V | L7: B | M7: P | N7: S | O7: I
A8: =A7+1 -> 6 | J8: CA
A9: =A8+1 -> 7 | J9: 1 liv.
A10: =A9+1 -> 8 | J10: 2 liv.
A11: =A10+1 -> 9 | J11: 3 liv.
A12: =A11+1 -> 10 | J12: 4 liv.
A13: =A12+1 -> 11 | J13: 5 liv.
A14: =A13+1 -> 12 | J14: Cariche
A15: =A14+1 -> 13 | J15: A. Santa
A16: =A15+1 -> 14 | J16: Olio
A17: =A16+1 -> 15 | J17: Torcie
A18: =A17+1 -> 16 | J18: Dardi
A19: =A18+1 -> 17 | J19: Quadrelli
... A22: =A21+1 -> 20 | J22: Pietre
Q23: =10
A24: THAC0 | C24: CA | D24: CA | E24: CA | F24: CA | G24: CA | H24: CA | I24: CA | J24: CA | K24: CA | L24: CA | M24: CA | N24: CA | O24: CA | P24: CA | Q24: CA
C25: -3 | D25: =C25+1 -> -2 | E25: =D25+1 -> -1 | F25: =E25+1 -> 0 | G25: =F25+1 -> 1 | H25: =G25+1 -> 2 | I25: =H25+1 -> 3 | J25: =I25+1 -> 4 | K25: =J25+1 -> 5 | ... Q25: =P25+1 -> 11
A26: 19 | C26: =$A26-C$25 -> 22 | D26: =$A26-D$25 -> 21 | E26: =$A26-E$25 -> 20 | F26: =$A26-F$25 -> 19 | G26: =$A26-G$25 -> 18 | H26: =$A26-H$25 -> 17 | I26: =$A26-I$25 -> 16 | J26: =$A26-J$25 -> 15 | ... Q26: =$A26-Q$25 -> 8
A27: 18 | C27: =$A27-C$25 -> 21 | D27: =$A27-D$25 -> 20 | E27: =$A27-E$25 -> 19 | F27: =$A27-F$25 -> 18 | G27: =$A27-G$25 -> 17 | H27: =$A27-H$25 -> 16 | I27: =$A27-I$25 -> 15 | J27: =$A27-J$25 -> 14 | ... Q27: =$A27-Q$25 -> 7
A28: 17 | C28: =$A28-C$25 -> 20 | D28: =$A28-D$25 -> 19 | E28: =$A28-E$25 -> 18 | F28: =$A28-F$25 -> 17 | G28: =$A28-G$25 -> 16 | H28: =$A28-H$25 -> 15 | I28: =$A28-I$25 -> 14 | J28: =$A28-J$25 -> 13 | ... Q28: =$A28-Q$25 -> 6
A29: 16 | C29: =$A29-C$25 -> 19 | D29: =$A29-D$25 -> 18 | E29: =$A29-E$25 -> 17 | F29: =$A29-F$25 -> 16 | G29: =$A29-G$25 -> 15 | H29: =$A29-H$25 -> 14 | I29: =$A29-I$25 -> 13 | J29: =$A29-J$25 -> 12 | ... Q29: =$A29-Q$25 -> 5
A30: 15 | C30: =$A30-C$25 -> 18 | D30: =$A30-D$25 -> 17 | E30: =$A30-E$25 -> 16 | F30: =$A30-F$25 -> 15 | G30: =$A30-G$25 -> 14 | H30: =$A30-H$25 -> 13 | I30: =$A30-I$25 -> 12 | J30: =$A30-J$25 -> 11 | ... Q30: =$A30-Q$25 -> 4
A31: 14 | C31: =$A31-C$25 -> 17 | D31: =$A31-D$25 -> 16 | E31: =$A31-E$25 -> 15 | F31: =$A31-F$25 -> 14 | G31: =$A31-G$25 -> 13 | H31: =$A31-H$25 -> 12 | I31: =$A31-I$25 -> 11 | J31: =$A31-J$25 -> 10 | ... Q31: =$A31-Q$25 -> 3
A32: 13 | C32: =$A32-C$25 -> 16 | D32: =$A32-D$25 -> 15 | E32: =$A32-E$25 -> 14 | F32: =$A32-F$25 -> 13 | G32: =$A32-G$25 -> 12 | H32: =$A32-H$25 -> 11 | I32: =$A32-I$25 -> 10 | J32: =$A32-J$25 -> 9 | ... Q32: =$A32-Q$25 -> 2
A33: 12 | C33: =$A33-C$25 -> 15 | D33: =$A33-D$25 -> 14 | E33: =$A33-E$25 -> 13 | F33: =$A33-F$25 -> 12 | G33: =$A33-G$25 -> 11 | H33: =$A33-H$25 -> 10 | I33: =$A33-I$25 -> 9 | J33: =$A33-J$25 -> 8 | ... Q33: =$A33-Q$25 -> 1
A34: 11 | C34: =$A34-C$25 -> 14 | D34: =$A34-D$25 -> 13 | E34: =$A34-E$25 -> 12 | F34: =$A34-F$25 -> 11 | G34: =$A34-G$25 -> 10 | H34: =$A34-H$25 -> 9 | I34: =$A34-I$25 -> 8 | J34: =$A34-J$25 -> 7 | ... Q34: =$A34-Q$25 -> 0
Q35: THAC0 - Tiro = CA Colpita
A37: Slot | B37: Esempio | K37: Armatura | M37: CA | N37: Slot | O37: U/E | P37: N | Q37: H
A38: 0 | B38: Anelli, amuleti, pergamene, chiavi, gemme | K38: Nessuna | M38: 9 | N38: 0 | O38: 40' | P38: 20' | Q38: 30'
A39: 1/3 | B39: Pozioni, acqua santa (fiale) | K39: Imbottita | M39: 8 | N39: 1 | O39: 40' | P39: 20' | Q39: 30'
A40: 1/2 | B40: Olio (fiasche) | K40: Cuoio | M40: 7 | N40: 2 | P40: 20' | Q40: 30'
A41: 1 | B41: Armi piccole, torce (6), corda, faretra, bacchette, sacco (+3 slot) | K41: Cuoio Borchiato | M41: 6 | N41: 2 | O41: 40' | P41: 20' | Q41: 30'
A42: 2 | B42: Armi medie, arm. leggere, scudo, arco c., balestra l., stivali, mantello | K42: Cotta di maglie | M42: 1d8+3 | N42: 2 | O42: 30' | P42: 20' | Q42: 20'
A43: 3 | B43: Armi grandi, armatura pesante, scudo grande, arco lungo, balestra p. | K43: Arm. a bande | M43: 4 | N43: 3 | O43: 20' | P43: 20' | Q43: -
...

Sheet Dwarf
A1: Giocatore | B1: Seska Poluth | G1: Nano Corazzato Resistente | K1: Esperienza | N1: 30.000
A2: Razza | B2: Nano | E2: Classe | G2: Nano | I2: 5° | K2: Allineamento | N2: Neutrale
A4: CA | B4: 2 | E4: Slot | F4: 22 | G4: +7 | H4: ½ Mov. | L4: Iniziativa | M4: 0 | O4: PF | P4: 44
A5: Abilità | J5: Mod. | M5: Tiri salvezza
A6: 13 | B6: FOR | C6: Apre porte bloccate con 1-3 su 1d6 | J6: 1 | M6: Veleno, Raggio della Morte | P6: 6
A7: 10 | B7: DES | C7: Nessun modificatore | J7: 0 | M7: Bacchetta | P7: 7
A8: 16 | B8: COS | C8: Bonus punti ferita aggiunti al totale | J8: 2 | M8: Pietrificazione Paralisi | P8: 8
A9: 10 | B9: INT | C9: Legge e scrive nella lingua nativa | J9: 0 | M9: Soffio Drago | P9: 10
A10: 13 | B10: SAG | C10: Bonus ai TS contro magia | J10: 1 | M10: Incantesimi Bastone Magico | P10: 9
A11: 11 | B11: CAR | C11: Reazioni PNG +0, massimo 4 seguaci, morale seguaci 7 | J11: 0 | M11: TS: 1D20 ≥ valore TS = Successo TA: 1D20 ≤ valore attributo = Successo
A13: Lingue Parlate | D13: Movimento | H13: Piedi | I13: Metri | J13: Quad. | K13: Sprint | L13: Malus | N13: Slot/Equipaggiamento
A14: Common, Nanco, Gnomesco, Koboldo,Goblin | D14: Combattimento | G14: 1R | H14: 20 | I14: =J14*1.5 -> 6 | J14: =H14/5 -> 4 | K14: 8 dm | L14: - | N14: 3/Armatura a piastre
D15: Esplorazione | G15: 1T | H15: 60 | I15: =J15*1.5 -> 18 | J15: =H15/5 -> 12 | K15: - | L15: - | N15: 1/Pugnali (2)
D16: Correre | G16: 1R | H16: 60 | I16: =J16*1.5 -> 18 | J16: =H16/5 -> 12 | K16: =J16+(J16/2) -> 18 | L16: -2 Tiri 10R (max 3 R) | N16: 2/Arco Corto
A17: THAC0 - Tiro = CA Colpita | D17: Arrampicarsi | G17: 1R | H17: 10 | I17: =J17*1.5 -> 3 | J17: =H17/5 -> 2 | K17: =J17+(J17/2) -> 3 | N17: 0/Vestiti, Cintura, Stivali
A18: 1R = 10 Sec. | 1T = 10 Min. | D18: Nuotare | G18: 1R | H18: 10 | I18: =J18*1.5 -> 3 | J18: =H18/5 -> 2 | K18: =J18+(J18/2) -> 3 | N18: 2/Ascia da Battaglia + 1
D19: Giornaliero | G19: 1G | H19: 12 mi | I19: 19km | K19: - | L19: - | N19: 2/Scudo
N20: 1/Faretra
A21: Carica +2TxC +2CA min.4□ | Ritirata difensiva ½Mv nega attacco nemico | Difesa totale -2CA ½Mv
A22: Spinta 1d20+mod.FOR vs +1□ | Disarmo -4TxC | Parare(F) -4CA ½Mv | Colpo potente(F) -5TxC +5PF | O22: Slot | P22: 11
A23: Afferrrare TxC vs CA, Liberarsi da presa 1d20+mod.FOR vs, Azione Pronta inter. turno nemico
A24: Scambiare Posizione ½Mv | Attraversare alleati +1□ | Passare oggetto: chi passa usa azione | O24: Banca | P24: Trasportati
A25: Combattimento in fila: 2* fila armi lunghe | Preparare per carica Dannox2 | N25: pp
A26: Prone: +2 TxC nemici, ½Mv per alzarsi | Raccolgiere arma: Mov.+Racc. o Racc.+Att. | N26: mo | P26: 500
A27: Copertura: Parziale -2TxC +2CA, Quasi Tot. -4TxC +4CA | Area: Parz. +2 TS, Quasi Tot. +4 TS | N27: ma
A28: Tiro oltre 1* PG/Mostri: -2TxC Lancio/-4TxC Tiro, 1/1-2 Colpito Alleato | N28: mr
A29: TxC Distanza: corta +1, normale 0, lunga -1 | O29: Slot | P29: 5
A31: Combinazioni | C31: CA | N31: Abilità
A32: Ascia/pugnale + Scudo | C32: 2 | N32: 1/6 trovare porte segrete
A33: Ascia due mani | C33: 3 | N33: 1/6 Ascoltare rumori
A34: Arco Corto | C34: 3 | N34: 1/6 ascoltare attr. Porte
A35: Pugnale | C35: 3 | N35: Infravsione 60'/12q
L40: THAC0
A41: Arma | B41: Range | C41: AC 9 | D41: 8 | E41: =D41-1 -> 7 | F41: =E41-1 -> 6 | G41: =F41-1 -> 5 | H41: =G41-1 -> 4 | I41: =H41-1 -> 3 | J41: =I41-1 -> 2 | K41: =J41-1 -> 1 | L41: =K41-1 -> 0 | M41: Danno | O41: Note
A42: Ascia da B. | B42: melee lenta | C42: 6 | D42: =C42+1 -> 7 | E42: =D42+1 -> 8 | F42: =E42+1 -> 9 | G42: =F42+1 -> 10 | H42: =G42+1 -> 11 | I42: =H42+1 -> 12 | J42: =I42+1 -> 13 | K42: =J42+1 -> 14 | L42: =K42+1 -> 15 | M42: 1d8+2 | O42: 1 mano 1d6+2
A43: Pugnale | B43: melee | C43: 7 | D43: =C43+1 -> 8 | E43: =D43+1 -> 9 | F43: =E43+1 -> 10 | G43: =F43+1 -> 11 | H43: =G43+1 -> 12 | I43: =H43+1 -> 13 | J43: =I43+1 -> 14 | K43: =J43+1 -> 15 | L43: =K43+1 -> 16 | M43: 1d4+1 | O43: lanciabile 10/20/30'
A44: Arco Corto | B44: 50/100/150 | C44: 8 | D44: =C44+1 -> 9 | E44: =D44+1 -> 10 | F44: =E44+1 -> 11 | G44: =F44+1 -> 12 | H44: =G44+1 -> 13 | I44: =H44+1 -> 14 | J44: =I44+1 -> 15 | K44: =J44+1 -> 16 | L44: =K44+1 -> 17 | M44: 1d6 | O44: 12 freccie

Sheet Retro N
A1: Slot Totali | C1: =Dwarf!F4 -> 22 | E1: Sovraccarico | G1: =Dwarf!G4 -> +7 | I1: Slot Bonus | M1: Slot Occupati | O1: =Dwarf!P22+Dwarf!P29 -> 16
A2: Oggetto | H2: Qt. | I2: Slot | J2: STATS
A3: 1 | J3: PF
A4: =A3+1 -> 2
A5: =A4+1 -> 3
A6: =A5+1 -> 4 | J6: THACO0
A7: =A6+1 -> 5 | J7: +TS | K7: V | L7: B | M7: P | N7: S | O7: I
A8: =A7+1 -> 6 | J8: CA
A9: =A8+1 -> 7 | J9: 1 liv.
A10: =A9+1 -> 8 | J10: 2 liv.
A11: =A10+1 -> 9 | J11: 3 liv.
A12: =A11+1 -> 10 | J12: 4 liv.
A13: =A12+1 -> 11 | J13: 5 liv.
A14: =A13+1 -> 12 | J14: Cariche
A15: =A14+1 -> 13 | J15: A. Santa
A16: =A15+1 -> 14 | J16: Olio
A17: =A16+1 -> 15 | J17: Torcie
A18: =A17+1 -> 16 | J18: Dardi
A19: =A18+1 -> 17 | J19: Quadrelli
... A22: =A21+1 -> 20 | J22: Pietre
Q23: =10
A24: THAC0 | C24: CA | D24: CA | E24: CA | F24: CA | G24: CA | H24: CA | I24: CA | J24: CA | K24: CA | L24: CA | M24: CA | N24: CA | O24: CA | P24: CA | Q24: CA
C25: -3 | D25: =C25+1 -> -2 | E25: =D25+1 -> -1 | F25: =E25+1 -> 0 | G25: =F25+1 -> 1 | H25: =G25+1 -> 2 | I25: =H25+1 -> 3 | J25: =I25+1 -> 4 | K25: =J25+1 -> 5 | ... Q25: =P25+1 -> 11
A26: 19 | C26: =$A26-C$25 -> 22 | D26: =$A26-D$25 -> 21 | E26: =$A26-E$25 -> 20 | F26: =$A26-F$25 -> 19 | G26: =$A26-G$25 -> 18 | H26: =$A26-H$25 -> 17 | I26: =$A26-I$25 -> 16 | J26: =$A26-J$25 -> 15 | ... Q26: =$A26-Q$25 -> 8
A27: 18 | C27: =$A27-C$25 -> 21 | D27: =$A27-D$25 -> 20 | E27: =$A27-E$25 -> 19 | F27: =$A27-F$25 -> 18 | G27: =$A27-G$25 -> 17 | H27: =$A27-H$25 -> 16 | I27: =$A27-I$25 -> 15 | J27: =$A27-J$25 -> 14 | ... Q27: =$A27-Q$25 -> 7
A28: 17 | C28: =$A28-C$25 -> 20 | D28: =$A28-D$25 -> 19 | E28: =$A28-E$25 -> 18 | F28: =$A28-F$25 -> 17 | G28: =$A28-G$25 -> 16 | H28: =$A28-H$25 -> 15 | I28: =$A28-I$25 -> 14 | J28: =$A28-J$25 -> 13 | ... Q28: =$A28-Q$25 -> 6
A29: 16 | C29: =$A29-C$25 -> 19 | D29: =$A29-D$25 -> 18 | E29: =$A29-E$25 -> 17 | F29: =$A29-F$25 -> 16 | G29: =$A29-G$25 -> 15 | H29: =$A29-H$25 -> 14 | I29: =$A29-I$25 -> 13 | J29: =$A29-J$25 -> 12 | ... Q29: =$A29-Q$25 -> 5
A30: 15 | C30: =$A30-C$25 -> 18 | D30: =$A30-D$25 -> 17 | E30: =$A30-E$25 -> 16 | F30: =$A30-F$25 -> 15 | G30: =$A30-G$25 -> 14 | H30: =$A30-H$25 -> 13 | I30: =$A30-I$25 -> 12 | J30: =$A30-J$25 -> 11 | ... Q30: =$A30-Q$25 -> 4
A31: 14 | C31: =$A31-C$25 -> 17 | D31: =$A31-D$25 -> 16 | E31: =$A31-E$25 -> 15 | F31: =$A31-F$25 -> 14 | G31: =$A31-G$25 -> 13 | H31: =$A31-H$25 -> 12 | I31: =$A31-I$25 -> 11 | J31: =$A31-J$25 -> 10 | ... Q31: =$A31-Q$25 -> 3
A32: 13 | C32: =$A32-C$25 -> 16 | D32: =$A32-D$25 -> 15 | E32: =$A32-E$25 -> 14 | F32: =$A32-F$25 -> 13 | G32: =$A32-G$25 -> 12 | H32: =$A32-H$25 -> 11 | I32: =$A32-I$25 -> 10 | J32: =$A32-J$25 -> 9 | ... Q32: =$A32-Q$25 -> 2
A33: 12 | C33: =$A33-C$25 -> 15 | D33: =$A33-D$25 -> 14 | E33: =$A33-E$25 -> 13 | F33: =$A33-F$25 -> 12 | G33: =$A33-G$25 -> 11 | H33: =$A33-H$25 -> 10 | I33: =$A33-I$25 -> 9 | J33: =$A33-J$25 -> 8 | ... Q33: =$A33-Q$25 -> 1
A34: 11 | C34: =$A34-C$25 -> 14 | D34: =$A34-D$25 -> 13 | E34: =$A34-E$25 -> 12 | F34: =$A34-F$25 -> 11 | G34: =$A34-G$25 -> 10 | H34: =$A34-H$25 -> 9 | I34: =$A34-I$25 -> 8 | J34: =$A34-J$25 -> 7 | ... Q34: =$A34-Q$25 -> 0
Q35: THAC0 - Tiro = CA Colpita
A37: Slot | B37: Esempio | K37: Armatura | M37: CA | N37: Slot | O37: U/E | P37: N | Q37: H
A38: 0 | B38: Anelli, amuleti, pergamene, chiavi, gemme | K38: Nessuna | M38: 9 | N38: 0 | O38: 40' | P38: 20' | Q38: 30'
A39: 1/3 | B39: Pozioni, acqua santa (fiale) | K39: Imbottita | M39: 8 | N39: 1 | O39: 40' | P39: 20' | Q39: 30'
A40: 1/2 | B40: Olio (fiasche) | K40: Cuoio | M40: 7 | N40: 2 | P40: 20' | Q40: 30'
A41: 1 | B41: Armi piccole, torce (6), corda, faretra, bacchette, sacco (+3 slot) | K41: Cuoio Borchiato | M41: 6 | N41: 2 | O41: 40' | P41: 20' | Q41: 30'
A42: 2 | B42: Armi medie, arm. leggere, scudo, arco c., balestra l., stivali, mantello | K42: Cotta di maglie | M42: 5 | N42: 2 | O42: 30' | P42: 20' | Q42: 20'
A43: 3 | B43: Armi grandi, armatura pesante, scudo grande, arco lungo, balestra p. | K43: Arm. a bande | M43: 4 | N43: 3 | O43: 20' | P43: 20' | Q43: -
...

Sheet Thief
A1: Giocatore | B1: Cesaire Thorn | G1: Agile Furtivo Preciso | K1: Esperienza | N1: 30.000
A2: Razza | B2: Umano | E2: Classe | G2: Ladro | I2: 6° | K2: Allineamento | N2: Neutrale
A4: CA | B4: 4 | E4: Slot | F4: 20 | G4: +6 | H4: ½ Mov. | L4: Iniziativa | M4: 2 | O4: PF | P4: 26
A5: Abilità | J5: Mod. | M5: Tiri salvezza
A6: 9 | B6: FOR | C6: Apre porte bloccate con 1-2 su 1d6 | J6: 0 | M6: Veleno, Raggio della Morte | P6: 12
A7: 16 | B7: DES | C7: Bonus a attacchi a distanza, CA, iniziativa | J7: 2 | M7: Bacchetta | P7: 13
A8: 13 | B8: COS | C8: Bonus punti ferita aggiunti al totale | J8: 1 | M8: Pietrificazione Paralisi | P8: 11
A9: 14 | B9: INT | C9: Legge e scrive più lingue | J9: 1 | M9: Soffio Drago | P9: 14
A10: 6 | B10: SAG | C10: Penalità ai TS contro magia | J10: -1 | M10: Incantesimi Bastone Magico | P10: 12
A11: 10 | B11: CAR | C11: Reazioni PNG +0, massimo 4 seguaci, morale seguaci 7 | J11: 0 | M11: TS: 1D20 ≥ valore TS = Successo TA: 1D20 ≤ valore attributo = Successo
A13: Lingue Parlate | D13: Movimento | H13: Piedi | I13: Metri | J13: Quad. | K13: Sprint | L13: Malus | N13: Slot/Equipaggiamento
A14: Common, Nanco, Gnomesco, Koboldo,Goblin | D14: Combattimento | G14: 1R | H14: 40 | I14: =J14*1.5 -> 12 | J14: =H14/5 -> 8 | K14: 16 dm | L14: - | N14: 2/Armatura di cuoio +1
D15: Esplorazione | G15: 1T | H15: =H14*3 -> 120 | I15: =J15*1.5 -> 36 | J15: =H15/5 -> 24 | K15: - | L15: - | N15: 1/Pugnali (2)
D16: Correre | G16: 1R | H16: =H14*3 -> 120 | I16: =J16*1.5 -> 36 | J16: =H16/5 -> 24 | K16: =J16+(J16/2) -> 36 | L16: -2 Tiri 10R (max 3 R) | N16: 2/Arco Corto
A17: THAC0 - Tiro = CA Colpita | D17: Arrampicarsi | G17: 1R | H17: =H14/2 -> 20 | I17: =J17*1.5 -> 6 | J17: =H17/5 -> 4 | K17: =J17+(J17/2) -> 6 | N17: 0/Vestiti, Cintura, Stivali
A18: 1R = 10 Sec. | 1T = 10 Min. | D18: Nuotare | G18: 1R | H18: =H14/2 -> 20 | I18: =J18*1.5 -> 6 | J18: =H18/5 -> 4 | K18: =J18+(J18/2) -> 6 | N18: 1/Atrezzi da scasso
D19: Giornaliero | G19: 1G | H19: 24mi | I19: 38km | K19: - | L19: - | N19: 2/Spada
N20: 1/Faretra
A21: Carica +2TxC +2CA min.4□ | Ritirata difensiva ½Mv nega attacco nemico | Difesa totale -2CA ½Mv
A22: Spinta 1d20+mod.FOR vs +1□ | Disarmo -4TxC | Parare(F) -4CA ½Mv | Colpo potente(F) -5TxC +5PF | O22: Slot | P22: 9
A23: Afferrrare TxC vs CA, Liberarsi da presa 1d20+mod.FOR vs, Azione Pronta inter. turno nemico
A24: Scambiare Posizione ½Mv | Attraversare alleati +1□ | Passare oggetto: chi passa usa azione | O24: Banca | P24: Trasportati
A25: Combattimento in fila: 2* fila armi lunghe | Preparare per carica Dannox2 | N25: pp
A26: Prone: +2 TxC nemici, ½Mv per alzarsi | Raccolgiere arma: Mov.+Racc. o Racc.+Att. | N26: mo | P26: 500
A27: Copertura: Parziale -2TxC +2CA, Quasi Tot. -4TxC +4CA | Area: Parz. +2 TS, Quasi Tot. +4 TS | N27: ma
A28: Tiro oltre 1* PG/Mostri: -2TxC Lancio/-4TxC Tiro, 1/1-2 Colpito Alleato | N28: mr
A29: TxC Distanza: corta +1, normale 0, lunga -1 | O29: Slot | P29: 5
A32: Scassinare | C32: 0.45 | E32: Scalare Parti Lisce | J32: 0.92 | N32: Abilità
A33: Trov./Rim. Trappole | C33: 0.4 | E33: Nascondersi nelle Ombre | J33: 0.36 | N33: 1/6 trovare porte segrete
A34: Borseggiare | C34: 0.45 | E34: Leg. Lingue non Magiche | J34: 0.8 | N34: 3/6 Ascoltare rumori
A35: Muoversi Silenziosamente | C35: 0.45 | E35: Attacco alle Spalle +4 TxC, Danno x 2 | N35: 3/6 ascoltare attr. Porte
L40: THAC0
A41: Arma | B41: Range | C41: AC 9 | D41: 8 | E41: =D41-1 -> 7 | F41: =E41-1 -> 6 | G41: =F41-1 -> 5 | H41: =G41-1 -> 4 | I41: =H41-1 -> 3 | J41: =I41-1 -> 2 | K41: =J41-1 -> 1 | L41: =K41-1 -> 0 | M41: Danno | O41: Note
A42: Spada | B42: melee | C42: 8 | D42: =C42+1 -> 9 | E42: =D42+1 -> 10 | F42: =E42+1 -> 11 | G42: =F42+1 -> 12 | H42: =G42+1 -> 13 | I42: =H42+1 -> 14 | J42: =I42+1 -> 15 | K42: =J42+1 -> 16 | L42: =K42+1 -> 17 | M42: 1d8
A43: Pugnale | B43: melee | C43: 8 | D43: =C43+1 -> 9 | E43: =D43+1 -> 10 | F43: =E43+1 -> 11 | G43: =F43+1 -> 12 | H43: =G43+1 -> 13 | I43: =H43+1 -> 14 | J43: =I43+1 -> 15 | K43: =J43+1 -> 16 | L43: =K43+1 -> 17 | M43: 1d4 | O43: lanciabile 10/20/30'
A44: Arco Corto | B44: 50/100/150' | C44: 6 | D44: =C44+1 -> 7 | E44: =D44+1 -> 8 | F44: =E44+1 -> 9 | G44: =F44+1 -> 10 | H44: =G44+1 -> 11 | I44: =H44+1 -> 12 | J44: =I44+1 -> 13 | K44: =J44+1 -> 14 | L44: =K44+1 -> 15 | M44: 1d6 | O44: 12 freccie

Sheet Retro L
A1: Slot Totali | C1: =Thief!F4 -> 20 | E1: Sovraccarico | G1: =Thief!G4 -> +6 | I1: Slot Bonus | M1: Slot Occupati | O1: =Thief!P22+Thief!P29 -> 14
A2: Oggetto | H2: Qt. | I2: Slot | J2: STATS
A3: 1 | J3: PF
A4: =A3+1 -> 2
A5: =A4+1 -> 3
A6: =A5+1 -> 4 | J6: THACO0
A7: =A6+1 -> 5 | J7: +TS | K7: V | L7: B | M7: P | N7: S | O7: I
A8: =A7+1 -> 6 | J8: CA
A9: =A8+1 -> 7 | J9: 1 liv.
A10: =A9+1 -> 8 | J10: 2 liv.
A11: =A10+1 -> 9 | J11: 3 liv.
A12: =A11+1 -> 10 | J12: 4 liv.
A13: =A12+1 -> 11 | J13: 5 liv.
A14: =A13+1 -> 12 | J14: Cariche
A15: =A14+1 -> 13 | J15: A. Santa
A16: =A15+1 -> 14 | J16: Olio
A17: =A16+1 -> 15 | J17: Torcie
A18: =A17+1 -> 16 | J18: Dardi
A19: =A18+1 -> 17 | J19: Quadrelli
... A22: =A21+1 -> 20 | J22: Pietre
Q23: =10
A24: THAC0 | C24: CA | D24: CA | E24: CA | F24: CA | G24: CA | H24: CA | I24: CA | J24: CA | K24: CA | L24: CA | M24: CA | N24: CA | O24: CA | P24: CA | Q24: CA
C25: -3 | D25: =C25+1 -> -2 | E25: =D25+1 -> -1 | F25: =E25+1 -> 0 | G25: =F25+1 -> 1 | H25: =G25+1 -> 2 | I25: =H25+1 -> 3 | J25: =I25+1 -> 4 | K25: =J25+1 -> 5 | ... Q25: =P25+1 -> 11
A26: 19 | C26: =$A26-C$25 -> 22 | D26: =$A26-D$25 -> 21 | E26: =$A26-E$25 -> 20 | F26: =$A26-F$25 -> 19 | G26: =$A26-G$25 -> 18 | H26: =$A26-H$25 -> 17 | I26: =$A26-I$25 -> 16 | J26: =$A26-J$25 -> 15 | ... Q26: =$A26-Q$25 -> 8
A27: 18 | C27: =$A27-C$25 -> 21 | D27: =$A27-D$25 -> 20 | E27: =$A27-E$25 -> 19 | F27: =$A27-F$25 -> 18 | G27: =$A27-G$25 -> 17 | H27: =$A27-H$25 -> 16 | I27: =$A27-I$25 -> 15 | J27: =$A27-J$25 -> 14 | ... Q27: =$A27-Q$25 -> 7
A28: 17 | C28: =$A28-C$25 -> 20 | D28: =$A28-D$25 -> 19 | E28: =$A28-E$25 -> 18 | F28: =$A28-F$25 -> 17 | G28: =$A28-G$25 -> 16 | H28: =$A28-H$25 -> 15 | I28: =$A28-I$25 -> 14 | J28: =$A28-J$25 -> 13 | ... Q28: =$A28-Q$25 -> 6
A29: 16 | C29: =$A29-C$25 -> 19 | D29: =$A29-D$25 -> 18 | E29: =$A29-E$25 -> 17 | F29: =$A29-F$25 -> 16 | G29: =$A29-G$25 -> 15 | H29: =$A29-H$25 -> 14 | I29: =$A29-I$25 -> 13 | J29: =$A29-J$25 -> 12 | ... Q29: =$A29-Q$25 -> 5
A30: 15 | C30: =$A30-C$25 -> 18 | D30: =$A30-D$25 -> 17 | E30: =$A30-E$25 -> 16 | F30: =$A30-F$25 -> 15 | G30: =$A30-G$25 -> 14 | H30: =$A30-H$25 -> 13 | I30: =$A30-I$25 -> 12 | J30: =$A30-J$25 -> 11 | ... Q30: =$A30-Q$25 -> 4
A31: 14 | C31: =$A31-C$25 -> 17 | D31: =$A31-D$25 -> 16 | E31: =$A31-E$25 -> 15 | F31: =$A31-F$25 -> 14 | G31: =$A31-G$25 -> 13 | H31: =$A31-H$25 -> 12 | I31: =$A31-I$25 -> 11 | J31: =$A31-J$25 -> 10 | ... Q31: =$A31-Q$25 -> 3
A32: 13 | C32: =$A32-C$25 -> 16 | D32: =$A32-D$25 -> 15 | E32: =$A32-E$25 -> 14 | F32: =$A32-F$25 -> 13 | G32: =$A32-G$25 -> 12 | H32: =$A32-H$25 -> 11 | I32: =$A32-I$25 -> 10 | J32: =$A32-J$25 -> 9 | ... Q32: =$A32-Q$25 -> 2
A33: 12 | C33: =$A33-C$25 -> 15 | D33: =$A33-D$25 -> 14 | E33: =$A33-E$25 -> 13 | F33: =$A33-F$25 -> 12 | G33: =$A33-G$25 -> 11 | H33: =$A33-H$25 -> 10 | I33: =$A33-I$25 -> 9 | J33: =$A33-J$25 -> 8 | ... Q33: =$A33-Q$25 -> 1
A34: 11 | C34: =$A34-C$25 -> 14 | D34: =$A34-D$25 -> 13 | E34: =$A34-E$25 -> 12 | F34: =$A34-F$25 -> 11 | G34: =$A34-G$25 -> 10 | H34: =$A34-H$25 -> 9 | I34: =$A34-I$25 -> 8 | J34: =$A34-J$25 -> 7 | ... Q34: =$A34-Q$25 -> 0
Q35: THAC0 - Tiro = CA Colpita
A37: Slot | B37: Esempio | K37: Armatura | M37: CA | N37: Slot | O37: U/E | P37: N | Q37: H
A38: 0 | B38: Anelli, amuleti, pergamene, chiavi, gemme | K38: Nessuna | M38: 9 | N38: 0 | O38: 40' | P38: 20' | Q38: 30'
A39: 1/3 | B39: Pozioni, acqua santa (fiale) | K39: Imbottita | M39: 8 | N39: 1 | O39: 40' | P39: 20' | Q39: 30'
A40: 1/2 | B40: Olio (fiasche) | K40: Cuoio | M40: 7 | N40: 2 | P40: 20' | Q40: 30'
A41: 1 | B41: Armi piccole, torce (6), corda, faretra, bacchette, sacco (+3 slot) | K41: Cuoio Borchiato | M41: 6 | N41: 2 | O41: 40' | P41: 20' | Q41: 30'
A42: 2 | B42: Armi medie, arm. leggere, scudo, arco c., balestra l., stivali, mantello | K42: Cotta di maglie | M42: 5 | N42: 2 | O42: 30' | P42: 20' | Q42: 20'
A43: 3 | B43: Armi grandi, armatura pesante, scudo grande, arco lungo, balestra p. | K43: Arm. a bande | M43: 4 | N43: 3 | O43: 20' | P43: 20' | Q43: -
...

Sheet Mage
A1: Giocatore | B1: Juven Lionsbane | G1: Fragile Arcano Potente | K1: Esperienza | N1: 30.000
A2: Razza | B2: Umano | E2: Classe | G2: Mago | I2: 5° | K2: Allineamento | N2: Neutrale
A4: CA | B4: 8 | E4: Slot | F4: 18 | G4: +5 | H4: ½ Mov. | L4: Iniziativa | M4: 0 | O4: PF | P4: 21
A5: Abilità | J5: Mod. | M5: Tiri salvezza
A6: 8 | B6: FOR | C6: Apre porte bloccate con 1 su 1d6 | J6: -1 | M6: Veleno, Raggio della Morte | P6: 13
A7: 10 | B7: DES | C7: Nessun modificatore | J7: 0 | M7: Bacchetta | P7: 14
A8: 13 | B8: COS | C8: Bonus punti ferita aggiunti al totale | J8: 1 | M8: Pietrificazione Paralisi | P8: 13
A9: 16 | B9: INT | C9: Legge e scrive più lingue | J9: 2 | M9: Soffio Drago | P9: 16
A10: 9 | B10: SAG | C10: Nessun modificatore | J10: 0 | M10: Incantesimi Bastone Magico | P10: 15
A11: 8 | B11: CAR | C11: Reazioni PNG -1, massimo 3 seguaci, morale seguaci 6 | J11: -1 | M11: TS: 1D20 ≥ valore TS = Successo TA: 1D20 ≤ valore attributo = Successo
A13: Lingue Parlate | D13: Movimento | H13: Piedi | I13: Metri | J13: Quad. | K13: Sprint | L13: Malus | N13: Slot/Equipaggiamento
A14: Common, Nanco, Gnomesco, Koboldo,Goblin | D14: Combattimento | G14: 1R | H14: 40 | I14: =J14*1.5 -> 12 | J14: =H14/5 -> 8 | K14: 16 dm | L14: - | N14: 2/Bastone + 1
D15: Esplorazione | G15: 1T | H15: =H14*3 -> 120 | I15: =J15*1.5 -> 36 | J15: =H15/5 -> 24 | K15: - | L15: - | N15: 1/Pugnali (2)
D16: Correre | G16: 1R | H16: =H14*3 -> 120 | I16: =J16*1.5 -> 36 | J16: =H16/5 -> 24 | K16: =J16+(J16/2) -> 36 | L16: -2 Tiri 10R (max 3 R) | N16: 0/Vestiti, Cintura, Stivali
A17: THAC0 - Tiro = CA Colpita | D17: Arrampicarsi | G17: 1R | H17: =H14/2 -> 20 | I17: =J17*1.5 -> 6 | J17: =H17/5 -> 4 | K17: =J17+(J17/2) -> 6 | N17: 1/Libro Incantesimi
A18: 1R = 10 Sec. | 1T = 10 Min. | D18: Nuotare | G18: 1R | H18: =H14/2 -> 20 | I18: =J18*1.5 -> 6 | J18: =H18/5 -> 4 | K18: =J18+(J18/2) -> 6
D19: Giornaliero | G19: 1G | H19: 24mi | I19: 38km | K19: - | L19: -
A21: Carica +2TxC +2CA min.4□ | Ritirata difensiva ½Mv nega attacco nemico | Difesa totale -2CA ½Mv
A22: Spinta 1d20+mod.FOR vs +1□ | Disarmo -4TxC | Parare(F) -4CA ½Mv | Colpo potente(F) -5TxC +5PF | O22: Slot | P22: 4
A23: Afferrrare TxC vs CA, Liberarsi da presa 1d20+mod.FOR vs, Azione Pronta inter. turno nemico
A24: Scambiare Posizione ½Mv | Attraversare alleati +1□ | Passare oggetto: chi passa usa azione | O24: Banca | P24: Trasportati
A25: Combattimento in fila: 2* fila armi lunghe | Preparare per carica Dannox2 | N25: pp
A26: Prone: +2 TxC nemici, ½Mv per alzarsi | Raccolgiere arma: Mov.+Racc. o Racc.+Att. | N26: mo | P26: 500
A27: Copertura: Parziale -2TxC +2CA, Quasi Tot. -4TxC +4CA | Area: Parz. +2 TS, Quasi Tot. +4 TS | N27: ma
A28: Tiro oltre 1* PG/Mostri: -2TxC Lancio/-4TxC Tiro, 1/1-2 Colpito Alleato | N28: mr
A29: TxC Distanza: corta +1, normale 0, lunga -1 | O29: Slot | P29: 5
A32: Incantesimi Scelti | C32: 1°/2 | E32: 2°/2 | G32: 3°/1 | N32: Abilità
A33: 1 Livello | B33: Dardo Incantato 2d6+2 150, Scudo CA2 | N33: 1/6 trovare porte segrete
A34: 2 Livello | B34: Immagine Speculare 1d4 6T, Levitare 11T | N34: 1/6 Ascoltare rumori
A35: 3 Livello | B35: Palla di Fuoco 5d6 G48□ R4□ | N35: 1/6 ascoltare attr. Porte
L40: THAC0
A41: Arma | B41: Range | C41: AC 9 | D41: 8 | E41: =D41-1 -> 7 | F41: =E41-1 -> 6 | G41: =F41-1 -> 5 | H41: =G41-1 -> 4 | I41: =H41-1 -> 3 | J41: =I41-1 -> 2 | K41: =J41-1 -> 1 | L41: =K41-1 -> 0 | M41: Danno | O41: Note
A42: Bastone | B42: melee | C42: 10 | D42: =C42+1 -> 11 | E42: =D42+1 -> 12 | F42: =E42+1 -> 13 | G42: =F42+1 -> 14 | H42: =G42+1 -> 15 | I42: =H42+1 -> 16 | J42: =I42+1 -> 17 | K42: =J42+1 -> 18 | L42: =K42+1 -> 19 | M42: 1d4
A43: Pugnale | B43: melee | C43: 11 | D43: =C43+1 -> 12 | E43: =D43+1 -> 13 | F43: =E43+1 -> 14 | G43: =F43+1 -> 15 | H43: =G43+1 -> 16 | I43: =H43+1 -> 17 | J43: =I43+1 -> 18 | K43: =J43+1 -> 19 | L43: =K43+1 -> 20 | M43: 1d4-1
A44: Pugnale | B44: 10/20/30' | C44: 10 | D44: =C44+1 -> 11 | E44: =D44+1 -> 12 | F44: =E44+1 -> 13 | G44: =F44+1 -> 14 | H44: =G44+1 -> 15 | I44: =H44+1 -> 16 | J44: =I44+1 -> 17 | K44: =J44+1 -> 18 | L44: =K44+1 -> 19 | M44: 1d4

Sheet Retro M
A1: Slot Totali | C1: =Mage!F4 -> 18 | E1: Sovraccarico | G1: =Mage!G4 -> +5 | I1: Slot Bonus | M1: Slot Occupati | O1: =Mage!P22+Mage!P29 -> 9
A2: Oggetto | H2: Qt. | I2: Slot | J2: STATS
A3: 1 | J3: PF
A4: =A3+1 -> 2
A5: =A4+1 -> 3
A6: =A5+1 -> 4 | J6: THACO0
A7: =A6+1 -> 5 | J7: +TS | K7: V | L7: B | M7: P | N7: S | O7: I
A8: =A7+1 -> 6 | J8: CA
A9: =A8+1 -> 7 | J9: 1 liv.
A10: =A9+1 -> 8 | J10: 2 liv.
A11: =A10+1 -> 9 | J11: 3 liv.
A12: =A11+1 -> 10 | J12: 4 liv.
A13: =A12+1 -> 11 | J13: 5 liv.
A14: =A13+1 -> 12 | J14: Cariche
A15: =A14+1 -> 13 | J15: A. Santa
A16: =A15+1 -> 14 | J16: Olio
A17: =A16+1 -> 15 | J17: Torcie
A18: =A17+1 -> 16 | J18: Dardi
A19: =A18+1 -> 17 | J19: Quadrelli
... A22: =A21+1 -> 20 | J22: Pietre
Q23: =10
A24: THAC0 | C24: CA | D24: CA | E24: CA | F24: CA | G24: CA | H24: CA | I24: CA | J24: CA | K24: CA | L24: CA | M24: CA | N24: CA | O24: CA | P24: CA | Q24: CA
C25: -3 | D25: =C25+1 -> -2 | E25: =D25+1 -> -1 | F25: =E25+1 -> 0 | G25: =F25+1 -> 1 | H25: =G25+1 -> 2 | I25: =H25+1 -> 3 | J25: =I25+1 -> 4 | K25: =J25+1 -> 5 | ... Q25: =P25+1 -> 11
A26: 19 | C26: =$A26-C$25 -> 22 | D26: =$A26-D$25 -> 21 | E26: =$A26-E$25 -> 20 | F26: =$A26-F$25 -> 19 | G26: =$A26-G$25 -> 18 | H26: =$A26-H$25 -> 17 | I26: =$A26-I$25 -> 16 | J26: =$A26-J$25 -> 15 | ... Q26: =$A26-Q$25 -> 8
A27: 18 | C27: =$A27-C$25 -> 21 | D27: =$A27-D$25 -> 20 | E27: =$A27-E$25 -> 19 | F27: =$A27-F$25 -> 18 | G27: =$A27-G$25 -> 17 | H27: =$A27-H$25 -> 16 | I27: =$A27-I$25 -> 15 | J27: =$A27-J$25 -> 14 | ... Q27: =$A27-Q$25 -> 7
A28: 17 | C28: =$A28-C$25 -> 20 | D28: =$A28-D$25 -> 19 | E28: =$A28-E$25 -> 18 | F28: =$A28-F$25 -> 17 | G28: =$A28-G$25 -> 16 | H28: =$A28-H$25 -> 15 | I28: =$A28-I$25 -> 14 | J28: =$A28-J$25 -> 13 | ... Q28: =$A28-Q$25 -> 6
A29: 16 | C29: =$A29-C$25 -> 19 | D29: =$A29-D$25 -> 18 | E29: =$A29-E$25 -> 17 | F29: =$A29-F$25 -> 16 | G29: =$A29-G$25 -> 15 | H29: =$A29-H$25 -> 14 | I29: =$A29-I$25 -> 13 | J29: =$A29-J$25 -> 12 | ... Q29: =$A29-Q$25 -> 5
A30: 15 | C30: =$A30-C$25 -> 18 | D30: =$A30-D$25 -> 17 | E30: =$A30-E$25 -> 16 | F30: =$A30-F$25 -> 15 | G30: =$A30-G$25 -> 14 | H30: =$A30-H$25 -> 13 | I30: =$A30-I$25 -> 12 | J30: =$A30-J$25 -> 11 | ... Q30: =$A30-Q$25 -> 4
A31: 14 | C31: =$A31-C$25 -> 17 | D31: =$A31-D$25 -> 16 | E31: =$A31-E$25 -> 15 | F31: =$A31-F$25 -> 14 | G31: =$A31-G$25 -> 13 | H31: =$A31-H$25 -> 12 | I31: =$A31-I$25 -> 11 | J31: =$A31-J$25 -> 10 | ... Q31: =$A31-Q$25 -> 3
A32: 13 | C32: =$A32-C$25 -> 16 | D32: =$A32-D$25 -> 15 | E32: =$A32-E$25 -> 14 | F32: =$A32-F$25 -> 13 | G32: =$A32-G$25 -> 12 | H32: =$A32-H$25 -> 11 | I32: =$A32-I$25 -> 10 | J32: =$A32-J$25 -> 9 | ... Q32: =$A32-Q$25 -> 2
A33: 12 | C33: =$A33-C$25 -> 15 | D33: =$A33-D$25 -> 14 | E33: =$A33-E$25 -> 13 | F33: =$A33-F$25 -> 12 | G33: =$A33-G$25 -> 11 | H33: =$A33-H$25 -> 10 | I33: =$A33-I$25 -> 9 | J33: =$A33-J$25 -> 8 | ... Q33: =$A33-Q$25 -> 1
A34: 11 | C34: =$A34-C$25 -> 14 | D34: =$A34-D$25 -> 13 | E34: =$A34-E$25 -> 12 | F34: =$A34-F$25 -> 11 | G34: =$A34-G$25 -> 10 | H34: =$A34-H$25 -> 9 | I34: =$A34-I$25 -> 8 | J34: =$A34-J$25 -> 7 | ... Q34: =$A34-Q$25 -> 0
Q35: THAC0 - Tiro = CA Colpita
A37: Slot | B37: Esempio | K37: Armatura | M37: CA | N37: Slot | O37: U/E | P37: N | Q37: H
A38: 0 | B38: Anelli, amuleti, pergamene, chiavi, gemme | K38: Nessuna | M38: 9 | N38: 0 | O38: 40' | P38: 20' | Q38: 30'
A39: 1/3 | B39: Pozioni, acqua santa (fiale) | K39: Imbottita | M39: 8 | N39: 1 | O39: 40' | P39: 20' | Q39: 30'
A40: 1/2 | B40: Olio (fiasche) | K40: Cuoio | M40: 7 | N40: 2 | P40: 20' | Q40: 30'
A41: 1 | B41: Armi piccole, torce (6), corda, faretra, bacchette, sacco (+3 slot) | K41: Cuoio Borchiato | M41: 6 | N41: 2 | O41: 40' | P41: 20' | Q41: 30'
A42: 2 | B42: Armi medie, arm. leggere, scudo, arco c., balestra l., stivali, mantello | K42: Cotta di maglie | M42: 5 | N42: 2 | O42: 30' | P42: 20' | Q42: 20'
A43: 3 | B43: Armi grandi, armatura pesante, scudo grande, arco lungo, balestra p. | K43: Arm. a bande | M43: 4 | N43: 3 | O43: 20' | P43: 20' | Q43: -
...

Sheet Fighter
A1: Giocatore | B1: Ellis Drolle | G1: Guerriero Corazzato Arciere | K1: Esperienza | N1: 30.000
A2: Razza | B2: Umano | E2: Classe | G2: Guerriero | I2: 5° | K2: Allineamento | N2: Neutrale
A4: CA | B4: 2 | E4: Slot | F4: 24 | G4: +8 | H4: ½ Mov. | L4: Iniziativa | M4: 1 | O4: PF | P4: 35
A5: Abilità | J5: Mod. | M5: Tiri salvezza
A6: 17 | B6: FOR | C6: Apre porte bloccate con 1-4 su 1d6 | J6: 2 | M6: Veleno, Raggio della Morte | P6: 10
A7: 14 | B7: DES | C7: Bonus a attacchi a distanza, CA, iniziativa | J7: 1 | M7: Bacchetta | P7: 11
A8: 11 | B8: COS | C8: Nessun modificatore | J8: 0 | M8: Pietrificazione Paralisi | P8: 12
A9: 7 | B9: INT | C9: Sa scrivere parole semplici | J9: -1 | M9: Soffio Drago | P9: 13
A10: 4 | B10: SAG | C10: Penalità ai TS contro magia | J10: -2 | M10: Incantesimi Bastone Magico | P10: 16
A11: 10 | B11: CAR | C11: Reazioni PNG +0, massimo 4 seguaci, morale seguaci 7 | J11: 0 | M11: TS: 1D20 ≥ valore TS = Successo TA: 1D20 ≤ valore attributo = Successo
A13: Lingue Parlate | D13: Movimento | H13: Piedi | I13: Metri | J13: Quad. | K13: Sprint | L13: Malus | N13: Slot/Equipaggiamento
A14: Common, Nanco, Gnomesco, Koboldo,Goblin | D14: Combattimento | G14: 1R | H14: 20 | I14: =J14*1.5 -> 6 | J14: =H14/5 -> 4 | K14: 8 dm | L14: - | N14: 3/Armatura a piastre
D15: Esplorazione | G15: 1T | H15: 60 | I15: =J15*1.5 -> 18 | J15: =H15/5 -> 12 | K15: - | L15: - | N15: 1/Pugnali
D16: Correre | G16: 1R | H16: 60 | I16: =J16*1.5 -> 18 | J16: =H16/5 -> 12 | K16: =J16+(J16/2) -> 18 | L16: -2 Tiri 10R (max 3 R) | N16: 3/Arco Lungo
A17: THAC0 - Tiro = CA Colpita | D17: Arrampicarsi | G17: 1R | H17: 10 | I17: =J17*1.5 -> 3 | J17: =H17/5 -> 2 | K17: =J17+(J17/2) -> 3 | N17: 0/Vestiti, Cintura, Stivali
A18: 1R = 10 Sec. | 1T = 10 Min. | D18: Nuotare | G18: 1R | H18: 10 | I18: =J18*1.5 -> 3 | J18: =H18/5 -> 2 | K18: =J18+(J18/2) -> 3 | N18: 3/Spada a due mani + 1
D19: Giornaliero | G19: 1G | H19: 12 mi | I19: 19km | K19: - | L19: - | N19: 1/Faretra
A21: Carica +2TxC +2CA min.4□ | Ritirata difensiva ½Mv nega attacco nemico | Difesa totale -2CA ½Mv
A22: Spinta 1d20+mod.FOR vs +1□ | Disarmo -4TxC | Parare(F) -4CA ½Mv | Colpo potente(F) -5TxC +5PF | O22: Slot | P22: 11
A23: Afferrrare TxC vs CA, Liberarsi da presa 1d20+mod.FOR vs, Azione Pronta inter. turno nemico
A24: Scambiare Posizione ½Mv | Attraversare alleati +1□ | Passare oggetto: chi passa usa azione | O24: Banca | P24: Trasportati
A25: Combattimento in fila: 2* fila armi lunghe | Preparare per carica Dannox2 | N25: pp
A26: Prone: +2 TxC nemici, ½Mv per alzarsi | Raccolgiere arma: Mov.+Racc. o Racc.+Att. | N26: mo | P26: 500
A27: Copertura: Parziale -2TxC +2CA, Quasi Tot. -4TxC +4CA | Area: Parz. +2 TS, Quasi Tot. +4 TS | N27: ma
A28: Tiro oltre 1* PG/Mostri: -2TxC Lancio/-4TxC Tiro, 1/1-2 Colpito Alleato | N28: mr
A29: TxC Distanza: corta +1, normale 0, lunga -1 | O29: Slot | P29: 5
A31: Combinazioni | C31: CA
A32: Ascia/pugnale + Scudo | C32: 1 | N32: Abilità
A33: Spada due mani | C33: 2 | N33: 1/6 trovare porte segrete
A34: Arco lungo | C34: 2 | N34: 1/6 Ascoltare rumori
A35: Pugnale | C35: 2 | N35: 1/6 ascoltare attr. Porte
L40: THAC0
A41: Arma | B41: Range | C41: AC 9 | D41: 8 | E41: =D41-1 -> 7 | F41: =E41-1 -> 6 | G41: =F41-1 -> 5 | H41: =G41-1 -> 4 | I41: =H41-1 -> 3 | J41: =I41-1 -> 2 | K41: =J41-1 -> 1 | L41: =K41-1 -> 0 | M41: Danno | O41: Note
A42: S. due Mani | B42: melee lenta | C42: 5 | D42: =C42+1 -> 6 | E42: =D42+1 -> 7 | F42: =E42+1 -> 8 | G42: =F42+1 -> 9 | H42: =G42+1 -> 10 | I42: =H42+1 -> 11 | J42: =I42+1 -> 12 | K42: =J42+1 -> 13 | L42: =K42+1 -> 14 | M42: 1d10+3 | O42: Attacca per Ultimo
A43: Pugnale | B43: melee | C43: 6 | D43: =C43+1 -> 7 | E43: =D43+1 -> 8 | F43: =E43+1 -> 9 | G43: =F43+1 -> 10 | H43: =G43+1 -> 11 | I43: =H43+1 -> 12 | J43: =I43+1 -> 13 | K43: =J43+1 -> 14 | L43: =K43+1 -> 15 | M43: 1d4+2 | O43: lanciabile 10/20/30'
A44: Arco Lungo | B44: 70/140/210' | C44: 7 | D44: =C44+1 -> 8 | E44: =D44+1 -> 9 | F44: =E44+1 -> 10 | G44: =F44+1 -> 11 | H44: =G44+1 -> 12 | I44: =H44+1 -> 13 | J44: =I44+1 -> 14 | K44: =J44+1 -> 15 | L44: =K44+1 -> 16 | M44: 1d6 | O44: 12 freccie

Sheet Retro F
A1: Slot Totali | C1: =Fighter!F4 -> 24 | E1: Sovraccarico | G1: =Fighter!G4 -> +8 | I1: Slot Bonus | M1: Slot Occupati | O1: =Fighter!P22+Fighter!P29 -> 16
A2: Oggetto | H2: Qt. | I2: Slot | J2: STATS
A3: 1 | J3: PF
A4: =A3+1 -> 2
A5: =A4+1 -> 3
A6: =A5+1 -> 4 | J6: THACO0
A7: =A6+1 -> 5 | J7: +TS | K7: V | L7: B | M7: P | N7: S | O7: I
A8: =A7+1 -> 6 | J8: CA
A9: =A8+1 -> 7 | J9: 1 liv.
A10: =A9+1 -> 8 | J10: 2 liv.
A11: =A10+1 -> 9 | J11: 3 liv.
A12: =A11+1 -> 10 | J12: 4 liv.
A13: =A12+1 -> 11 | J13: 5 liv.
A14: =A13+1 -> 12 | J14: Cariche
A15: =A14+1 -> 13 | J15: A. Santa
A16: =A15+1 -> 14 | J16: Olio
A17: =A16+1 -> 15 | J17: Torcie
A18: =A17+1 -> 16 | J18: Dardi
A19: =A18+1 -> 17 | J19: Quadrelli
... A22: =A21+1 -> 20 | J22: Pietre
Q23: =10
A24: THAC0 | C24: CA | D24: CA | E24: CA | F24: CA | G24: CA | H24: CA | I24: CA | J24: CA | K24: CA | L24: CA | M24: CA | N24: CA | O24: CA | P24: CA | Q24: CA
C25: -3 | D25: =C25+1 -> -2 | E25: =D25+1 -> -1 | F25: =E25+1 -> 0 | G25: =F25+1 -> 1 | H25: =G25+1 -> 2 | I25: =H25+1 -> 3 | J25: =I25+1 -> 4 | K25: =J25+1 -> 5 | ... Q25: =P25+1 -> 11
A26: 19 | C26: =$A26-C$25 -> 22 | D26: =$A26-D$25 -> 21 | E26: =$A26-E$25 -> 20 | F26: =$A26-F$25 -> 19 | G26: =$A26-G$25 -> 18 | H26: =$A26-H$25 -> 17 | I26: =$A26-I$25 -> 16 | J26: =$A26-J$25 -> 15 | ... Q26: =$A26-Q$25 -> 8
A27: 18 | C27: =$A27-C$25 -> 21 | D27: =$A27-D$25 -> 20 | E27: =$A27-E$25 -> 19 | F27: =$A27-F$25 -> 18 | G27: =$A27-G$25 -> 17 | H27: =$A27-H$25 -> 16 | I27: =$A27-I$25 -> 15 | J27: =$A27-J$25 -> 14 | ... Q27: =$A27-Q$25 -> 7
A28: 17 | C28: =$A28-C$25 -> 20 | D28: =$A28-D$25 -> 19 | E28: =$A28-E$25 -> 18 | F28: =$A28-F$25 -> 17 | G28: =$A28-G$25 -> 16 | H28: =$A28-H$25 -> 15 | I28: =$A28-I$25 -> 14 | J28: =$A28-J$25 -> 13 | ... Q28: =$A28-Q$25 -> 6
A29: 16 | C29: =$A29-C$25 -> 19 | D29: =$A29-D$25 -> 18 | E29: =$A29-E$25 -> 17 | F29: =$A29-F$25 -> 16 | G29: =$A29-G$25 -> 15 | H29: =$A29-H$25 -> 14 | I29: =$A29-I$25 -> 13 | J29: =$A29-J$25 -> 12 | ... Q29: =$A29-Q$25 -> 5
A30: 15 | C30: =$A30-C$25 -> 18 | D30: =$A30-D$25 -> 17 | E30: =$A30-E$25 -> 16 | F30: =$A30-F$25 -> 15 | G30: =$A30-G$25 -> 14 | H30: =$A30-H$25 -> 13 | I30: =$A30-I$25 -> 12 | J30: =$A30-J$25 -> 11 | ... Q30: =$A30-Q$25 -> 4
A31: 14 | C31: =$A31-C$25 -> 17 | D31: =$A31-D$25 -> 16 | E31: =$A31-E$25 -> 15 | F31: =$A31-F$25 -> 14 | G31: =$A31-G$25 -> 13 | H31: =$A31-H$25 -> 12 | I31: =$A31-I$25 -> 11 | J31: =$A31-J$25 -> 10 | ... Q31: =$A31-Q$25 -> 3
A32: 13 | C32: =$A32-C$25 -> 16 | D32: =$A32-D$25 -> 15 | E32: =$A32-E$25 -> 14 | F32: =$A32-F$25 -> 13 | G32: =$A32-G$25 -> 12 | H32: =$A32-H$25 -> 11 | I32: =$A32-I$25 -> 10 | J32: =$A32-J$25 -> 9 | ... Q32: =$A32-Q$25 -> 2
A33: 12 | C33: =$A33-C$25 -> 15 | D33: =$A33-D$25 -> 14 | E33: =$A33-E$25 -> 13 | F33: =$A33-F$25 -> 12 | G33: =$A33-G$25 -> 11 | H33: =$A33-H$25 -> 10 | I33: =$A33-I$25 -> 9 | J33: =$A33-J$25 -> 8 | ... Q33: =$A33-Q$25 -> 1
A34: 11 | C34: =$A34-C$25 -> 14 | D34: =$A34-D$25 -> 13 | E34: =$A34-E$25 -> 12 | F34: =$A34-F$25 -> 11 | G34: =$A34-G$25 -> 10 | H34: =$A34-H$25 -> 9 | I34: =$A34-I$25 -> 8 | J34: =$A34-J$25 -> 7 | ... Q34: =$A34-Q$25 -> 0
Q35: THAC0 - Tiro = CA Colpita
A37: Slot | B37: Esempio | K37: Armatura | M37: CA | N37: Slot | O37: U/E | P37: N | Q37: H
A38: 0 | B38: Anelli, amuleti, pergamene, chiavi, gemme | K38: Nessuna | M38: 9 | N38: 0 | O38: 40' | P38: 20' | Q38: 30'
A39: 1/3 | B39: Pozioni, acqua santa (fiale) | K39: Imbottita | M39: 8 | N39: 1 | O39: 40' | P39: 20' | Q39: 30'
A40: 1/2 | B40: Olio (fiasche) | K40: Cuoio | M40: 7 | N40: 2 | P40: 20' | Q40: 30'
A41: 1 | B41: Armi piccole, torce (6), corda, faretra, bacchette, sacco (+3 slot) | K41: Cuoio Borchiato | M41: 6 | N41: 2 | O41: 40' | P41: 20' | Q41: 30'
A42: 2 | B42: Armi medie, arm. leggere, scudo, arco c., balestra l., stivali, mantello | K42: Cotta di maglie | M42: 5 | N42: 2 | O42: 30' | P42: 20' | Q42: 20'
A43: 3 | B43: Armi grandi, armatura pesante, scudo grande, arco lungo, balestra p. | K43: Arm. a bande | M43: 4 | N43: 3 | O43: 20' | P43: 20' | Q43: -
...

Sheet Cleric
A1: Giocatore | B1: Sutan Ambermoor | G1: Corazzato Lento Curatore | K1: Esperienza | N1: 30.000
A2: Razza | B2: Umano | E2: Classe | G2: Chierico | I2: 6° | K2: Allineamento | N2: Neutrale
A4: CA | B4: 2 | E4: Slot | F4: 20 | G4: +6 | H4: ½ Mov. | L4: Iniziativa | M4: -1 | O4: PF | P4: 31
A5: Abilità | J5: Mod. | M5: Tiri salvezza
A6: 12 | B6: FOR | C6: Apre porte bloccate con 1-2 su 1d6 | J6: 0 | M6: Veleno, Raggio della Morte | P6: 9
A7: 6 | B7: DES | C7: Penalità a attacchi a distanza -1, CA +1, iniziativa -1 | J7: -1 | M7: Bacchetta | P7: 10
A8: 12 | B8: COS | C8: Nessun modificatore | J8: 0 | M8: Pietrificazione Paralisi | P8: 12
A9: 7 | B9: INT | C9: Sa scrivere parole semplici | J9: -1 | M9: Soffio Drago | P9: 14
A10: 13 | B10: SAG | C10: +1 ai TS contro magia | J10: 1 | M10: Incantesimi Bastone Magico | P10: 11
A11: 9 | B11: CAR | C11: Reazioni PNG +0, massimo 4 seguaci, morale seguaci 7 | J11: 0 | M11: TS: 1D20 ≥ valore TS = Successo TA: 1D20 ≤ valore attributo = Successo
A13: Lingue Parlate | D13: Movimento | H13: Piedi | I13: Metri | J13: Quad. | K13: Sprint | L13: Malus | N13: Slot/Equipaggiamento
A14: Common, Nanco, Gnomesco, Koboldo,Goblin | D14: Combattimento | G14: 1R | H14: 20 | I14: =J14*1.5 -> 6 | J14: =H14/5 -> 4 | K14: 8 dm | L14: - | N14: 3/Armatura a piastre
D15: Esplorazione | G15: 1T | H15: 60 | I15: =J15*1.5 -> 18 | J15: =H15/5 -> 12 | K15: - | L15: - | N15: 1/Mazza
D16: Correre | G16: 1R | H16: 60 | I16: =J16*1.5 -> 18 | J16: =H16/5 -> 12 | K16: =J16+(J16/2) -> 18 | L16: -2 Tiri 10R (max 3 R) | N16: 1/Fionda
A17: THAC0 - Tiro = CA Colpita | D17: Arrampicarsi | G17: 1R | H17: 10 | I17: =J17*1.5 -> 3 | J17: =H17/5 -> 2 | K17: =J17+(J17/2) -> 3 | N17: 0/Vestiti, Cintura, Stivali
A18: 1R = 10 Sec. | 1T = 10 Min. | D18: Nuotare | G18: 1R | H18: 10 | I18: =J18*1.5 -> 3 | J18: =H18/5 -> 2 | K18: =J18+(J18/2) -> 3 | N18: 0/Simbolo sacro
D19: Giornaliero | G19: 1G | H19: 12mi | I19: 19km | K19: - | L19: - | N19: 1/Fiale Acqua santa (2)
N20: 2/Scudo +1
A21: Carica +2TxC +2CA min.4□ | Ritirata difensiva ½Mv nega attacco nemico | Difesa totale -2CA ½Mv
A22: Spinta 1d20+mod.FOR vs +1□ | Disarmo -4TxC | Parare(F) -4CA ½Mv | Colpo potente(F) -5TxC +5PF | O22: Slot | P22: 8
A23: Afferrrare TxC vs CA, Liberarsi da presa 1d20+mod.FOR vs, Azione Pronta inter. turno nemico
A24: Scambiare Posizione ½Mv | Attraversare alleati +1□ | Passare oggetto: chi passa usa azione | O24: Banca | P24: Trasportati
A25: Combattimento in fila: 2* fila armi lunghe | Preparare per carica Dannox2 | N25: pp
A26: Prone: +2 TxC nemici, ½Mv per alzarsi | Raccolgiere arma: Mov.+Racc. o Racc.+Att. | N26: mo | P26: 500
A27: Copertura: Parziale -2TxC +2CA, Quasi Tot. -4TxC +4CA | Area: Parz. +2 TS, Quasi Tot. +4 TS | N27: ma
A28: Tiro oltre 1* PG/Mostri: -2TxC Lancio/-4TxC Tiro, 1/1-2 Colpito Alleato | N28: mr
A29: TxC Distanza: corta +1, normale 0, lunga -1 | O29: Slot | P29: 5
A31: Incantesimi Scelti | C31: 1°/2 | E31: 2°/2 | G31: 3°/1 | I31: 4°/1 | N31: Abilità
A32: 1 Livello | B32: Cura Ferite Leggere 1d6+1, Protezione dal Male -1TxC 12T | N32: 1/6 trovare porte segrete
A33: 2 Livello | B33: Benedizione +1TxC 6R, Trovare Trap./Segr. 2T 30' | N33: 1/6 Ascoltare rumori
A34: 3 Livello | B34: Arma Potenziata +1d6 1T | N34: 1/6 ascoltare attr. Porte
A35: 4 Livello | B35: Cura Ferite Gravi 2d6+2 | N35: Scacciare 2d6
L40: THAC0
A41: Arma | B41: Range | C41: AC 9 | D41: 8 | E41: =D41-1 -> 7 | F41: =E41-1 -> 6 | G41: =F41-1 -> 5 | H41: =G41-1 -> 4 | I41: =H41-1 -> 3 | J41: =I41-1 -> 2 | K41: =J41-1 -> 1 | L41: =K41-1 -> 0 | M41: Danno | O41: Note
A42: Mazza | B42: melee | C42: 8 | D42: =C42+1 -> 9 | E42: =D42+1 -> 10 | F42: =E42+1 -> 11 | G42: =F42+1 -> 12 | H42: =G42+1 -> 13 | I42: =H42+1 -> 14 | J42: =I42+1 -> 15 | K42: =J42+1 -> 16 | L42: =K42+1 -> 17 | M42: 1d6
A43: Fionda | B43: 40/80/160' | C43: 8 | D43: =C43+1 -> 9 | E43: =D43+1 -> 10 | F43: =E43+1 -> 11 | G43: =F43+1 -> 12 | H43: =G43+1 -> 13 | I43: =H43+1 -> 14 | J43: =I43+1 -> 15 | K43: =J43+1 -> 16 | L43: =K43+1 -> 17 | M43: 1d4 | O43: 20 Pietre
A44: Acqua Santa | B44: 10/30/50' | C44: 9 | D44: =C44+1 -> 10 | E44: =D44+1 -> 11 | F44: =E44+1 -> 12 | G44: =F44+1 -> 13 | H44: =G44+1 -> 14 | I44: =H44+1 -> 15 | J44: =I44+1 -> 16 | K44: =J44+1 -> 17 | L44: =K44+1 -> 18 | M44: 1d8

Sheet Retro C
A1: Slot Totali | C1: =Cleric!F4 -> 20 | E1: Sovraccarico | G1: =Cleric!G4 -> +6 | I1: Slot Bonus | M1: Slot Occupati | O1: =Cleric!P22+Cleric!P29 -> 13
A2: Oggetto | H2: Qt. | I2: Slot | J2: STATS
A3: 1 | J3: PF
A4: =A3+1 -> 2
A5: =A4+1 -> 3
A6: =A5+1 -> 4 | J6: THACO0
A7: =A6+1 -> 5 | J7: +TS | K7: V | L7: B | M7: P | N7: S | O7: I
A8: =A7+1 -> 6 | J8: CA
A9: =A8+1 -> 7 | J9: 1 liv.
A10: =A9+1 -> 8 | J10: 2 liv.
A11: =A10+1 -> 9 | J11: 3 liv.
A12: =A11+1 -> 10 | J12: 4 liv.
A13: =A12+1 -> 11 | J13: 5 liv.
A14: =A13+1 -> 12 | J14: Cariche
A15: =A14+1 -> 13 | J15: A. Santa
A16: =A15+1 -> 14 | J16: Olio
A17: =A16+1 -> 15 | J17: Torcie
A18: =A17+1 -> 16 | J18: Dardi
A19: =A18+1 -> 17 | J19: Quadrelli
... A22: =A21+1 -> 20 | J22: Pietre
Q23: =10
A24: THAC0 | C24: CA | D24: CA | E24: CA | F24: CA | G24: CA | H24: CA | I24: CA | J24: CA | K24: CA | L24: CA | M24: CA | N24: CA | O24: CA | P24: CA | Q24: CA
C25: -3 | D25: =C25+1 -> -2 | E25: =D25+1 -> -1 | F25: =E25+1 -> 0 | G25: =F25+1 -> 1 | H25: =G25+1 -> 2 | I25: =H25+1 -> 3 | J25: =I25+1 -> 4 | K25: =J25+1 -> 5 | ... Q25: =P25+1 -> 11
A26: 19 | C26: =$A26-C$25 -> 22 | D26: =$A26-D$25 -> 21 | E26: =$A26-E$25 -> 20 | F26: =$A26-F$25 -> 19 | G26: =$A26-G$25 -> 18 | H26: =$A26-H$25 -> 17 | I26: =$A26-I$25 -> 16 | J26: =$A26-J$25 -> 15 | ... Q26: =$A26-Q$25 -> 8
A27: 18 | C27: =$A27-C$25 -> 21 | D27: =$A27-D$25 -> 20 | E27: =$A27-E$25 -> 19 | F27: =$A27-F$25 -> 18 | G27: =$A27-G$25 -> 17 | H27: =$A27-H$25 -> 16 | I27: =$A27-I$25 -> 15 | J27: =$A27-J$25 -> 14 | ... Q27: =$A27-Q$25 -> 7
A28: 17 | C28: =$A28-C$25 -> 20 | D28: =$A28-D$25 -> 19 | E28: =$A28-E$25 -> 18 | F28: =$A28-F$25 -> 17 | G28: =$A28-G$25 -> 16 | H28: =$A28-H$25 -> 15 | I28: =$A28-I$25 -> 14 | J28: =$A28-J$25 -> 13 | ... Q28: =$A28-Q$25 -> 6
A29: 16 | C29: =$A29-C$25 -> 19 | D29: =$A29-D$25 -> 18 | E29: =$A29-E$25 -> 17 | F29: =$A29-F$25 -> 16 | G29: =$A29-G$25 -> 15 | H29: =$A29-H$25 -> 14 | I29: =$A29-I$25 -> 13 | J29: =$A29-J$25 -> 12 | ... Q29: =$A29-Q$25 -> 5
A30: 15 | C30: =$A30-C$25 -> 18 | D30: =$A30-D$25 -> 17 | E30: =$A30-E$25 -> 16 | F30: =$A30-F$25 -> 15 | G30: =$A30-G$25 -> 14 | H30: =$A30-H$25 -> 13 | I30: =$A30-I$25 -> 12 | J30: =$A30-J$25 -> 11 | ... Q30: =$A30-Q$25 -> 4
A31: 14 | C31: =$A31-C$25 -> 17 | D31: =$A31-D$25 -> 16 | E31: =$A31-E$25 -> 15 | F31: =$A31-F$25 -> 14 | G31: =$A31-G$25 -> 13 | H31: =$A31-H$25 -> 12 | I31: =$A31-I$25 -> 11 | J31: =$A31-J$25 -> 10 | ... Q31: =$A31-Q$25 -> 3
A32: 13 | C32: =$A32-C$25 -> 16 | D32: =$A32-D$25 -> 15 | E32: =$A32-E$25 -> 14 | F32: =$A32-F$25 -> 13 | G32: =$A32-G$25 -> 12 | H32: =$A32-H$25 -> 11 | I32: =$A32-I$25 -> 10 | J32: =$A32-J$25 -> 9 | ... Q32: =$A32-Q$25 -> 2
A33: 12 | C33: =$A33-C$25 -> 15 | D33: =$A33-D$25 -> 14 | E33: =$A33-E$25 -> 13 | F33: =$A33-F$25 -> 12 | G33: =$A33-G$25 -> 11 | H33: =$A33-H$25 -> 10 | I33: =$A33-I$25 -> 9 | J33: =$A33-J$25 -> 8 | ... Q33: =$A33-Q$25 -> 1
A34: 11 | C34: =$A34-C$25 -> 14 | D34: =$A34-D$25 -> 13 | E34: =$A34-E$25 -> 12 | F34: =$A34-F$25 -> 11 | G34: =$A34-G$25 -> 10 | H34: =$A34-H$25 -> 9 | I34: =$A34-I$25 -> 8 | J34: =$A34-J$25 -> 7 | ... Q34: =$A34-Q$25 -> 0
Q35: THAC0 - Tiro = CA Colpita
A37: Slot | B37: Esempio | K37: Armatura | M37: CA | N37: Slot | O37: U/E | P37: N | Q37: H
A38: 0 | B38: Anelli, amuleti, pergamene, chiavi, gemme | K38: Nessuna | M38: 9 | N38: 0 | O38: 40' | P38: 20' | Q38: 30'
A39: 1/3 | B39: Pozioni, acqua santa (fiale) | K39: Imbottita | M39: 8 | N39: 1 | O39: 40' | P39: 20' | Q39: 30'
A40: 1/2 | B40: Olio (fiasche) | K40: Cuoio | M40: 7 | N40: 2 | P40: 20' | Q40: 30'
A41: 1 | B41: Armi piccole, torce (6), corda, faretra, bacchette, sacco (+3 slot) | K41: Cuoio Borchiato | M41: 6 | N41: 2 | O41: 40' | P41: 20' | Q41: 30'
A42: 2 | B42: Armi medie, arm. leggere, scudo, arco c., balestra l., stivali, mantello | K42: Cotta di maglie | M42: 5 | N42: 2 | O42: 30' | P42: 20' | Q42: 20'
A43: 3 | B43: Armi grandi, armatura pesante, scudo grande, arco lungo, balestra p. | K43: Arm. a bande | M43: 4 | N43: 3 | O43: 20' | P43: 20' | Q43: -
...

Sheet Retro Master
A1: Slot Totali | E1: Sovraccarico | I1: Slot Bonus | M1: Slot Occupati
A2: Oggetto | H2: Qt. | I2: Slot | J2: STATS
A3: 1 | J3: PF
A4: =A3+1 -> 2
A5: =A4+1 -> 3
A6: =A5+1 -> 4 | J6: THACO0
A7: =A6+1 -> 5 | J7: +TS | K7: V | L7: B | M7: P | N7: S | O7: I
A8: =A7+1 -> 6 | J8: CA
A9: =A8+1 -> 7 | J9: 1 liv.
A10: =A9+1 -> 8 | J10: 2 liv.
A11: =A10+1 -> 9 | J11: 3 liv.
A12: =A11+1 -> 10 | J12: 4 liv.
A13: =A12+1 -> 11 | J13: 5 liv.
A14: =A13+1 -> 12 | J14: Cariche
A15: =A14+1 -> 13 | J15: A. Santa
A16: =A15+1 -> 14 | J16: Olio
A17: =A16+1 -> 15 | J17: Torcie
A18: =A17+1 -> 16 | J18: Dardi
A19: =A18+1 -> 17 | J19: Quadrelli
... A22: =A21+1 -> 20 | J22: Pietre
Q23: =10
A24: THAC0 | C24: CA | D24: CA | E24: CA | F24: CA | G24: CA | H24: CA | I24: CA | J24: CA | K24: CA | L24: CA | M24: CA | N24: CA | O24: CA | P24: CA | Q24: CA
C25: -3 | D25: =C25+1 -> -2 | E25: =D25+1 -> -1 | F25: =E25+1 -> 0 | G25: =F25+1 -> 1 | H25: =G25+1 -> 2 | I25: =H25+1 -> 3 | J25: =I25+1 -> 4 | K25: =J25+1 -> 5 | ... Q25: =P25+1 -> 11
A26: 19 | C26: =$A26-C$25 -> 22 | D26: =$A26-D$25 -> 21 | E26: =$A26-E$25 -> 20 | F26: =$A26-F$25 -> 19 | G26: =$A26-G$25 -> 18 | H26: =$A26-H$25 -> 17 | I26: =$A26-I$25 -> 16 | J26: =$A26-J$25 -> 15 | ... Q26: =$A26-Q$25 -> 8
A27: 18 | C27: =$A27-C$25 -> 21 | D27: =$A27-D$25 -> 20 | E27: =$A27-E$25 -> 19 | F27: =$A27-F$25 -> 18 | G27: =$A27-G$25 -> 17 | H27: =$A27-H$25 -> 16 | I27: =$A27-I$25 -> 15 | J27: =$A27-J$25 -> 14 | ... Q27: =$A27-Q$25 -> 7
A28: 17 | C28: =$A28-C$25 -> 20 | D28: =$A28-D$25 -> 19 | E28: =$A28-E$25 -> 18 | F28: =$A28-F$25 -> 17 | G28: =$A28-G$25 -> 16 | H28: =$A28-H$25 -> 15 | I28: =$A28-I$25 -> 14 | J28: =$A28-J$25 -> 13 | ... Q28: =$A28-Q$25 -> 6
